Workbook

Sheet Cover
A1: Sony Group Corporation — three-statement model and DCF valuation
A2: Built by Alia Alami from Sony's Form 20-F for FY2025 (year ended March 31, 2026). Educational portfolio project, not investment advice.
A4: How the model flows
A5: 1. Historical | B5: Reported segment sales, income statement, balance sheet and cash flow from the SEC filing.
A6: 2. Assumptions | B6: Every driver in one place, with a Base, Upside and Downside column and the source of each number.
A7: 3. Base / Upside / Downside | B7: Revenue build -> income statement -> balance sheet -> cash flow -> free cash flow -> DCF.
A8: 4. Scenarios | B8: Side-by-side scenario results and a WACC x terminal-growth sensitivity table.
A9: 5. Dashboard | B9: Headline valuation and charts.
A11: Colour code
A12: Blue text | B12: Hard-coded input (reported figure or assumption).
A13: Black text | B13: Formula.
A14: Green text | B14: Direct link to another sheet.
A15: Yellow fill | B15: Key assumption: change these first to test the valuation.
A16: Grey fill | B16: Forecast period.
A18: Integrity checks
A19: Balance sheet | B19: Assets equal liabilities plus equity in every forecast year (Scenarios sheet, 'Balance check').
A20: Cash | B20: Balance-sheet cash is the closing cash from the cash-flow statement.
A22: Simplifications to know about
A23: Financial Services | B23: Spun off in FY2025 and presented as a discontinued operation, so it is excluded from the forecast and the valuation.
A24: Long-term assets | B24: PP&E, right-of-use, content and intangible assets are forecast as one line: prior + investment - D&A.
A25: Leases and debt | B25: Held flat; lease liabilities are treated as debt in the equity bridge.
A26: Other items | B26: Other operating items, equity-method income, goodwill changes and currency effects are assumed nil.

Sheet Dashboard
A1: Sony Group — valuation dashboard
A2: All figures are live links to the model. ¥ millions unless stated.
A4: Base value per share | C4: Market price per share | E4: Base value vs. market | G4: Enterprise value (¥ tn) | I4: WACC | K4: Terminal value share of EV
A5: =Base!C107 | C5: =Base!C109 | E5: =Base!C110 | G5: =Base!C98/1000000 | I5: =Assumptions!$C$50 | K5: =Base!C111

Sheet Historical
A1: Sony Group Corporation — reported financials
A2: ¥ millions. FY2025 = fiscal year ended March 31, 2026. Continuing operations (Financial Services, spun off in FY2025, is excluded from income and cash flow).
A3: Source: Sony Group Form 20-F FY2025 (SEC EDGAR, filed 2026-06-18), https://www.sec.gov/Archives/edgar/data/313838/000119312526274893/d28719d20f.htm. Segment sales for FY2021–FY2022 from the FY2023 Form 20-F.
A5: Segment sales | B5: FY2021 | C5: FY2022 | D5: FY2023 | E5: FY2024 | F5: FY2025
A6: Game & Network Services | B6: 2739763 | C6: 3644598 | D6: 4267734 | E6: 4670044 | F6: 4685651
A7: Music | B7: 1116949 | C7: 1380632 | D7: 1618958 | E7: 1842604 | F7: 2120110
A8: Pictures | B8: 1238911 | C8: 1369422 | D8: 1493050 | E8: 1505944 | F8: 1499290
A9: Entertainment Technology & Services | B9: 2339186 | C9: 2476025 | D9: 2453718 | E9: 2409275 | F9: 2260532
A10: Imaging & Sensing Solutions | B10: 1076424 | C10: 1402187 | D10: 1602738 | E10: 1799005 | F10: 2151533
A11: All Other | B11: 98783 | C11: 87623 | D11: 89370 | E11: 96333 | F11: 89072
A13: Income statement | B13: FY2021 | C13: FY2022 | D13: FY2023 | E13: FY2024 | F13: FY2025
A14: Sales | D14: 11260037 | E14: 12034917 | F14: 12479620
A15: Cost of sales | D15: 8089317 | E15: 8504810 | F15: 8635225
A16: Selling, general and administrative | D16: 2156156 | E16: 2256829 | F16: 2298638
A17: Other operating (income) expense, net | D17: -10134 | E17: -11222 | F17: 34056
A18: Share of profit (loss) of equity-method investments | D18: 10557 | E18: -7865 | F18: -64194
A19: Operating income | D19: 1035255 | E19: 1276635 | F19: 1447507
A20: Financial income | D20: 125597 | E20: 139024 | F20: 76041
A21: Financial expenses | D21: 65766 | E21: 72461 | F21: 101174
A22: Income before income taxes | D22: 1095086 | E22: 1343198 | F22: 1422374
A23: Income taxes | D23: 239105 | E23: 257480 | F23: 367108
A24: Net income from continuing operations | D24: 855981 | E24: 1085718 | F24: 1055266
A25: Net income (loss) from discontinued operations | D25: 124513 | E25: 74169 | F25: -1357758
... A27: Depreciation and amortization | D27: 1117292 | E27: 1125588 | F27: 1180655
A29: Balance sheet (March 31 following the fiscal year) | B29: FY2021 | C29: FY2022 | D29: FY2023 | E29: FY2024 | F29: FY2025
A30: Cash and cash equivalents | E30: 2980956 | F30: 2208879
A31: Investments and advances in the Financial Services segment (current) | E31: 453677 | F31: 0
A32: Trade and other receivables, and contract assets | E32: 1943184 | F32: 1821916
A33: Inventories | E33: 1310770 | F33: 1227351
A34: Other financial assets (current) | E34: 145192 | F34: 28167
A35: Other current assets | E35: 621209 | F35: 663678
A36: Total current assets | E36: 7454988 | F36: 5949991
A37: Investments accounted for using the equity method | E37: 347718 | F37: 483709
A38: Investments and advances in the Financial Services segment (non-current) | E38: 18736298 | F38: 0
A39: Property, plant and equipment | E39: 1513660 | F39: 1453805
A40: Right-of-use assets | E40: 521685 | F40: 524345
A41: Goodwill | E41: 1508721 | F41: 1673906
... A73: Total liabilities and equity | E73: 35293173 | F73: 15683490
A75: Cash flow (selected lines) | B75: FY2021 | C75: FY2022 | D75: FY2023 | E75: FY2024 | F75: FY2025
A76: Net cash from operating activities (continuing) | D76: 1103645 | E76: 1971349 | F76: 1966292
...

Sheet Assumptions
A1: Assumptions
A2: Blue = input you can change. Black = calculated. Yellow = key assumption that drives the scenarios. Each scenario sheet reads its own column.
A4: Driver | B4: Unit | C4: Base | D4: Upside | E4: Downside | F4: Source / rationale
A5: Revenue
A6: Game & Network Services: starting growth (FY2026) | B6: % yoy | C6: 0.0033 | D6: =$C6 | E6: =$C6 | F6: forecast_revenue.py: Naive (last year's growth) (raw 0.3%, capped to -5%..+12%)
A7: Music: starting growth (FY2026) | B7: % yoy | C7: 0.12 | D7: =$C7 | E7: =$C7 | F7: forecast_revenue.py: Naive (last year's growth) (raw 15.1%, capped to -5%..+12%)
A8: Pictures: starting growth (FY2026) | B8: % yoy | C8: -0.0044 | D8: =$C8 | E8: =$C8 | F8: forecast_revenue.py: Naive (last year's growth) (raw -0.4%, capped to -5%..+12%)
A9: Entertainment Technology & Services: starting growth (FY2026) | B9: % yoy | C9: -0.05 | D9: =$C9 | E9: =$C9 | F9: forecast_revenue.py: Naive (last year's growth) (raw -6.2%, capped to -5%..+12%)
A10: Imaging & Sensing Solutions: starting growth (FY2026) | B10: % yoy | C10: 0.12 | D10: =$C10 | E10: =$C10 | F10: forecast_revenue.py: Naive (last year's growth) (raw 19.6%, capped to -5%..+12%)
A11: All Other: starting growth (FY2026) | B11: % yoy | C11: -0.05 | D11: =$C11 | E11: =$C11 | F11: forecast_revenue.py: Naive (last year's growth) (raw -7.5%, capped to -5%..+12%)
A12: Scenario adjustment to every segment's growth | B12: pp | C12: 0 | D12: 0.02 | E12: -0.02 | F12: Analyst assumption: +/-2 points of growth a year in the upside/downside case
A13: Long-run growth each segment fades to by FY2030 | B13: % yoy | C13: 0.02 | D13: =$C13 | E13: =$C13 | F13: Analyst assumption; matches LONG_RUN_GROWTH in forecast_revenue.py
A14: Corporate and intersegment elimination | B14: % of segment sales | C14: =1-Historical!$F$14/(Historical!$F$6+Historical!$F$7+Historical!$F$8+Historical!$F$9+Historical!$F$10+Historical!$F$11) | D14: =$C14 | E14: =$C14 | F14: FY2025 actual: segment sales less consolidated sales
A15: Margins and reinvestment
A16: Cost of sales | B16: % of sales | C16: 0.692 | D16: 0.682 | E16: 0.707 | F16: FY2023-25 actual: 71.8%, 70.7%, 69.2%. Base holds FY2025; downside is about the 3-yr average (70.6%)
A17: Selling, general and administrative | B17: % of sales | C17: 0.184 | D17: =$C17 | E17: =$C17 | F17: FY2025 actual 18.4% (FY2023-24: 19.1%, 18.8%)
A18: Depreciation and amortization | B18: % of sales | C18: 0.095 | D18: =$C18 | E18: =$C18 | F18: FY2025 actual 9.5%; includes amortization of film and other content assets
A19: Capital expenditure (PP&E and intangibles) | B19: % of sales | C19: 0.047 | D19: =$C19 | E19: =$C19 | F19: FY2023-25 average (5.4%, 5.2%, 3.7%)
A20: Investment in content assets | B20: % of sales | C20: 0.051 | D20: =$C20 | E20: =$C20 | F20: FY2023-25 average (4.3%, 5.7%, 5.3%); Sony reports this within operating cash flow
A21: Tax rate | B21: % of pre-tax income | C21: 0.26 | D21: =$C21 | E21: =$C21 | F21: FY2025 effective rate 25.8%; Japanese statutory rate 31.5% (Form 20-F income taxes note)
A22: Working capital (held at FY2025 levels)
A23: Receivable days | B23: days of sales | C23: =Historical!$F$32/Historical!$F$14*365 | D23: =$C23 | E23: =$C23 | F23: FY2025 actual
A24: Inventory days | B24: days of cost of sales | C24: =Historical!$F$33/Historical!$F$15*365 | D24: =$C24 | E24: =$C24 | F24: FY2025 actual
A25: Payable days | B25: days of cost of sales | C25: =Historical!$F$52/Historical!$F$15*365 | D25: =$C25 | E25: =$C25 | F25: FY2025 actual
A26: Other current assets | B26: % of sales | C26: =(Historical!$F$34+Historical!$F$35)/Historical!$F$14 | D26: =$C26 | E26: =$C26 | F26: FY2025 actual
A27: Other current liabilities | B27: % of sales | C27: =(Historical!$F$54+Historical!$F$55+Historical!$F$56+Historical!$F$57+Historical!$F$58)/Historical!$F$14 | D27: =$C27 | E27: =$C27 | F27: FY2025 actual; taxes payable, contract liabilities, participations, other
A28: Financing
A29: Interest earned on opening cash | B29: % | C29: 0.015 | D29: =$C29 | E29: =$C29 | F29: Analyst assumption
A30: Interest paid on opening debt and leases | B30: % | C30: 0.035 | D30: =$C30 | E30: =$C30 | F30: Analyst assumption, in line with the pre-tax cost of debt below
A31: Dividend payout | B31: % of net income | C31: 0.13 | D31: =$C31 | E31: =$C31 | F31: FY2025 actual 12.8% of continuing net income
A32: Share repurchases per year | B32: ¥ millions | C32: 300000 | D32: =$C32 | E32: =$C32 | F32: Analyst assumption; FY2023-25 actual: 203bn, 286bn, 522bn
A33: Net new borrowing per year | B33: ¥ millions | C33: 0 | D33: =$C33 | E33: =$C33 | F33: Analyst assumption: maturing debt is refinanced
A34: Valuation
A35: Terminal growth rate | B35: % | C35: 0.02 | D35: 0.025 | E35: 0.015 | F35: Analyst assumption; below the 10-yr JGB yield so cash flows do not outgrow the risk-free rate
A36: Risk-free rate (10-yr Japanese government bond) | B36: % | C36: 0.03027 | D36: =$C36 | E36: =$C36 | F36: Japan Ministry of Finance, 2026-10-09
A37: Equity risk premium | B37: % | C37: 0.055 | D37: =$C37 | E37: =$C37 | F37: Analyst assumption, not sourced. Replace with your own estimate
A38: Equity beta | B38: x | C38: 1 | D38: =$C38 | E38: =$C38 | F38: Analyst assumption, not estimated from data. Replace with your own estimate
A39: Pre-tax cost of debt | B39: % | C39: 0.035 | D39: =$C39 | E39: =$C39 | F39: Analyst assumption: risk-free rate plus about 0.5 points
A40: Share price (ADR, 1 ADR = 1 share) | B40: US$ | C40: 24.15 | D40: =$C40 | E40: =$C40 | F40: Close on 2026-08-24 from project 6's price file
A41: Exchange rate | B41: ¥ per US$ | C41: 159.12 | D41: =$C41 | E41: =$C41 | F41: ECB reference rate, 2026-08-24
...

Sheet Base
A1: Sony Group — Base case: three statements and DCF
A2: ¥ millions unless stated. A = reported, E = forecast. Every forecast cell is a formula driven by the Base column of the Assumptions sheet.
B4: Driver | C4: FY2023A | D4: FY2024A | E4: FY2025A | F4: FY2026E | G4: FY2027E | H4: FY2028E | I4: FY2029E | J4: FY2030E
A5: Forecast year | F5: 1 | G5: 2 | H5: 3 | I5: 4 | J5: 5
A7: REVENUE BUILD
A8: Game & Network Services | C8: =Historical!$D$6 | D8: =Historical!$E$6 | E8: =Historical!$F$6 | F8: =E8*(1+F9) | G8: =F8*(1+G9) | H8: =G8*(1+H9) | I8: =H8*(1+I9) | J8: =I8*(1+J9)
A9: growth | B9: start, fading to long-run | C9: =Historical!$D$6/Historical!$C$6-1 | D9: =Historical!$E$6/Historical!$D$6-1 | E9: =Historical!$F$6/Historical!$E$6-1 | F9: =Assumptions!$C$6+(Assumptions!$C$13-Assumptions!$C$6)*(F$5-1)/4+Assumptions!$C$12 | G9: =Assumptions!$C$6+(Assumptions!$C$13-Assumptions!$C$6)*(G$5-1)/4+Assumptions!$C$12 | H9: =Assumptions!$C$6+(Assumptions!$C$13-Assumptions!$C$6)*(H$5-1)/4+Assumptions!$C$12 | I9: =Assumptions!$C$6+(Assumptions!$C$13-Assumptions!$C$6)*(I$5-1)/4+Assumptions!$C$12 | J9: =Assumptions!$C$6+(Assumptions!$C$13-Assumptions!$C$6)*(J$5-1)/4+Assumptions!$C$12
A10: Music | C10: =Historical!$D$7 | D10: =Historical!$E$7 | E10: =Historical!$F$7 | F10: =E10*(1+F11) | G10: =F10*(1+G11) | H10: =G10*(1+H11) | I10: =H10*(1+I11) | J10: =I10*(1+J11)
A11: growth | B11: start, fading to long-run | C11: =Historical!$D$7/Historical!$C$7-1 | D11: =Historical!$E$7/Historical!$D$7-1 | E11: =Historical!$F$7/Historical!$E$7-1 | F11: =Assumptions!$C$7+(Assumptions!$C$13-Assumptions!$C$7)*(F$5-1)/4+Assumptions!$C$12 | G11: =Assumptions!$C$7+(Assumptions!$C$13-Assumptions!$C$7)*(G$5-1)/4+Assumptions!$C$12 | H11: =Assumptions!$C$7+(Assumptions!$C$13-Assumptions!$C$7)*(H$5-1)/4+Assumptions!$C$12 | I11: =Assumptions!$C$7+(Assumptions!$C$13-Assumptions!$C$7)*(I$5-1)/4+Assumptions!$C$12 | J11: =Assumptions!$C$7+(Assumptions!$C$13-Assumptions!$C$7)*(J$5-1)/4+Assumptions!$C$12
A12: Pictures | C12: =Historical!$D$8 | D12: =Historical!$E$8 | E12: =Historical!$F$8 | F12: =E12*(1+F13) | G12: =F12*(1+G13) | H12: =G12*(1+H13) | I12: =H12*(1+I13) | J12: =I12*(1+J13)
A13: growth | B13: start, fading to long-run | C13: =Historical!$D$8/Historical!$C$8-1 | D13: =Historical!$E$8/Historical!$D$8-1 | E13: =Historical!$F$8/Historical!$E$8-1 | F13: =Assumptions!$C$8+(Assumptions!$C$13-Assumptions!$C$8)*(F$5-1)/4+Assumptions!$C$12 | G13: =Assumptions!$C$8+(Assumptions!$C$13-Assumptions!$C$8)*(G$5-1)/4+Assumptions!$C$12 | H13: =Assumptions!$C$8+(Assumptions!$C$13-Assumptions!$C$8)*(H$5-1)/4+Assumptions!$C$12 | I13: =Assumptions!$C$8+(Assumptions!$C$13-Assumptions!$C$8)*(I$5-1)/4+Assumptions!$C$12 | J13: =Assumptions!$C$8+(Assumptions!$C$13-Assumptions!$C$8)*(J$5-1)/4+Assumptions!$C$12
A14: Entertainment Technology & Services | C14: =Historical!$D$9 | D14: =Historical!$E$9 | E14: =Historical!$F$9 | F14: =E14*(1+F15) | G14: =F14*(1+G15) | H14: =G14*(1+H15) | I14: =H14*(1+I15) | J14: =I14*(1+J15)
A15: growth | B15: start, fading to long-run | C15: =Historical!$D$9/Historical!$C$9-1 | D15: =Historical!$E$9/Historical!$D$9-1 | E15: =Historical!$F$9/Historical!$E$9-1 | F15: =Assumptions!$C$9+(Assumptions!$C$13-Assumptions!$C$9)*(F$5-1)/4+Assumptions!$C$12 | G15: =Assumptions!$C$9+(Assumptions!$C$13-Assumptions!$C$9)*(G$5-1)/4+Assumptions!$C$12 | H15: =Assumptions!$C$9+(Assumptions!$C$13-Assumptions!$C$9)*(H$5-1)/4+Assumptions!$C$12 | I15: =Assumptions!$C$9+(Assumptions!$C$13-Assumptions!$C$9)*(I$5-1)/4+Assumptions!$C$12 | J15: =Assumptions!$C$9+(Assumptions!$C$13-Assumptions!$C$9)*(J$5-1)/4+Assumptions!$C$12
A16: Imaging & Sensing Solutions | C16: =Historical!$D$10 | D16: =Historical!$E$10 | E16: =Historical!$F$10 | F16: =E16*(1+F17) | G16: =F16*(1+G17) | H16: =G16*(1+H17) | I16: =H16*(1+I17) | J16: =I16*(1+J17)
A17: growth | B17: start, fading to long-run | C17: =Historical!$D$10/Historical!$C$10-1 | D17: =Historical!$E$10/Historical!$D$10-1 | E17: =Historical!$F$10/Historical!$E$10-1 | F17: =Assumptions!$C$10+(Assumptions!$C$13-Assumptions!$C$10)*(F$5-1)/4+Assumptions!$C$12 | G17: =Assumptions!$C$10+(Assumptions!$C$13-Assumptions!$C$10)*(G$5-1)/4+Assumptions!$C$12 | H17: =Assumptions!$C$10+(Assumptions!$C$13-Assumptions!$C$10)*(H$5-1)/4+Assumptions!$C$12 | I17: =Assumptions!$C$10+(Assumptions!$C$13-Assumptions!$C$10)*(I$5-1)/4+Assumptions!$C$12 | J17: =Assumptions!$C$10+(Assumptions!$C$13-Assumptions!$C$10)*(J$5-1)/4+Assumptions!$C$12
A18: All Other | C18: =Historical!$D$11 | D18: =Historical!$E$11 | E18: =Historical!$F$11 | F18: =E18*(1+F19) | G18: =F18*(1+G19) | H18: =G18*(1+H19) | I18: =H18*(1+I19) | J18: =I18*(1+J19)
A19: growth | B19: start, fading to long-run | C19: =Historical!$D$11/Historical!$C$11-1 | D19: =Historical!$E$11/Historical!$D$11-1 | E19: =Historical!$F$11/Historical!$E$11-1 | F19: =Assumptions!$C$11+(Assumptions!$C$13-Assumptions!$C$11)*(F$5-1)/4+Assumptions!$C$12 | G19: =Assumptions!$C$11+(Assumptions!$C$13-Assumptions!$C$11)*(G$5-1)/4+Assumptions!$C$12 | H19: =Assumptions!$C$11+(Assumptions!$C$13-Assumptions!$C$11)*(H$5-1)/4+Assumptions!$C$12 | I19: =Assumptions!$C$11+(Assumptions!$C$13-Assumptions!$C$11)*(I$5-1)/4+Assumptions!$C$12 | J19: =Assumptions!$C$11+(Assumptions!$C$13-Assumptions!$C$11)*(J$5-1)/4+Assumptions!$C$12
A20: Segment sales | C20: =C8+C10+C12+C14+C16+C18 | D20: =D8+D10+D12+D14+D16+D18 | E20: =E8+E10+E12+E14+E16+E18 | F20: =F8+F10+F12+F14+F16+F18 | G20: =G8+G10+G12+G14+G16+G18 | H20: =H8+H10+H12+H14+H16+H18 | I20: =I8+I10+I12+I14+I16+I18 | J20: =J8+J10+J12+J14+J16+J18
A21: Corporate and elimination | B21: % of segment sales | C21: =Historical!$D$14-C20 | D21: =Historical!$E$14-D20 | E21: =Historical!$F$14-E20 | F21: =-Assumptions!$C$14*F20 | G21: =-Assumptions!$C$14*G20 | H21: =-Assumptions!$C$14*H20 | I21: =-Assumptions!$C$14*I20 | J21: =-Assumptions!$C$14*J20
A23: INCOME STATEMENT
A24: Sales | C24: =Historical!$D$14 | D24: =Historical!$E$14 | E24: =Historical!$F$14 | F24: =F20+F21 | G24: =G20+G21 | H24: =H20+H21 | I24: =I20+I21 | J24: =J20+J21
A25: growth | D25: =D24/C24-1 | E25: =E24/D24-1 | F25: =F24/E24-1 | G25: =G24/F24-1 | H25: =H24/G24-1 | I25: =I24/H24-1 | J25: =J24/I24-1
A26: Cost of sales | B26: % of sales | C26: =Historical!$D$15 | D26: =Historical!$E$15 | E26: =Historical!$F$15 | F26: =Assumptions!$C$16*F24 | G26: =Assumptions!$C$16*G24 | H26: =Assumptions!$C$16*H24 | I26: =Assumptions!$C$16*I24 | J26: =Assumptions!$C$16*J24
A27: Gross profit | C27: =C24-C26 | D27: =D24-D26 | E27: =E24-E26 | F27: =F24-F26 | G27: =G24-G26 | H27: =H24-H26 | I27: =I24-I26 | J27: =J24-J26
A28: Selling, general and administrative | B28: % of sales | C28: =Historical!$D$16 | D28: =Historical!$E$16 | E28: =Historical!$F$16 | F28: =Assumptions!$C$17*F24 | G28: =Assumptions!$C$17*G24 | H28: =Assumptions!$C$17*H24 | I28: =Assumptions!$C$17*I24 | J28: =Assumptions!$C$17*J24
A29: Other operating (income) expense, net | B29: assumed nil | C29: =Historical!$D$17 | D29: =Historical!$E$17 | E29: =Historical!$F$17 | F29: =0 | G29: =0 | H29: =0 | I29: =0 | J29: =0
A30: Share of profit (loss) of equity-method investments | B30: assumed nil | C30: =Historical!$D$18 | D30: =Historical!$E$18 | E30: =Historical!$F$18 | F30: =0 | G30: =0 | H30: =0 | I30: =0 | J30: =0
A31: Operating income | C31: =C27-C28-C29+C30 | D31: =D27-D28-D29+D30 | E31: =E27-E28-E29+E30 | F31: =F27-F28-F29+F30 | G31: =G27-G28-G29+G30 | H31: =H27-H28-H29+H30 | I31: =I27-I28-I29+I30 | J31: =J27-J28-J29+J30
A32: operating margin | C32: =C31/C24 | D32: =D31/D24 | E32: =E31/E24 | F32: =F31/F24 | G32: =G31/G24 | H32: =H31/H24 | I32: =I31/I24 | J32: =J31/J24
A33: Financial income | B33: % of opening cash | C33: =Historical!$D$20 | D33: =Historical!$E$20 | E33: =Historical!$F$20 | F33: =Assumptions!$C$29*E42 | G33: =Assumptions!$C$29*F42 | H33: =Assumptions!$C$29*G42 | I33: =Assumptions!$C$29*H42 | J33: =Assumptions!$C$29*I42
A34: Financial expenses | B34: % of opening debt | C34: =Historical!$D$21 | D34: =Historical!$E$21 | E34: =Historical!$F$21 | F34: =Assumptions!$C$30*(E53+E54) | G34: =Assumptions!$C$30*(F53+F54) | H34: =Assumptions!$C$30*(G53+G54) | I34: =Assumptions!$C$30*(H53+H54) | J34: =Assumptions!$C$30*(I53+I54)
A35: Income before income taxes | C35: =C31+C33-C34 | D35: =D31+D33-D34 | E35: =E31+E33-E34 | F35: =F31+F33-F34 | G35: =G31+G33-G34 | H35: =H31+H33-H34 | I35: =I31+I33-I34 | J35: =J31+J33-J34
A36: Income taxes | B36: % of pre-tax income | C36: =Historical!$D$23 | D36: =Historical!$E$23 | E36: =Historical!$F$23 | F36: =Assumptions!$C$21*F35 | G36: =Assumptions!$C$21*G35 | H36: =Assumptions!$C$21*H35 | I36: =Assumptions!$C$21*I35 | J36: =Assumptions!$C$21*J35
A37: Net income from continuing operations | C37: =C35-C36 | D37: =D35-D36 | E37: =E35-E36 | F37: =F35-F36 | G37: =G35-G36 | H37: =H35-H36 | I37: =I35-I36 | J37: =J35-J36
A38: Depreciation and amortization (memo) | B38: % of sales | C38: =Historical!$D$27 | D38: =Historical!$E$27 | E38: =Historical!$F$27 | F38: =Assumptions!$C$18*F24 | G38: =Assumptions!$C$18*G24 | H38: =Assumptions!$C$18*H24 | I38: =Assumptions!$C$18*I24 | J38: =Assumptions!$C$18*J24
A39: EBITDA | C39: =C31+C38 | D39: =D31+D38 | E39: =E31+E38 | F39: =F31+F38 | G39: =G31+G38 | H39: =H31+H38 | I39: =I31+I38 | J39: =J31+J38
A41: BALANCE SHEET (March 31 following the fiscal year)
A42: Cash and cash equivalents | B42: from cash flow | D42: =Historical!$E$30 | E42: =Historical!$F$30 | F42: =F78 | G42: =G78 | H42: =H78 | I42: =I78 | J42: =J78
A43: Trade and other receivables | B43: days of sales | D43: =Historical!$E$32 | E43: =Historical!$F$32 | F43: =Assumptions!$C$23/365*F24 | G43: =Assumptions!$C$23/365*G24 | H43: =Assumptions!$C$23/365*H24 | I43: =Assumptions!$C$23/365*I24 | J43: =Assumptions!$C$23/365*J24
A44: Inventories | B44: days of cost of sales | D44: =Historical!$E$33 | E44: =Historical!$F$33 | F44: =Assumptions!$C$24/365*F26 | G44: =Assumptions!$C$24/365*G26 | H44: =Assumptions!$C$24/365*H26 | I44: =Assumptions!$C$24/365*I26 | J44: =Assumptions!$C$24/365*J26
...

Sheet Upside
A1: Sony Group — Upside case: three statements and DCF
A2: ¥ millions unless stated. A = reported, E = forecast. Every forecast cell is a formula driven by the Upside column of the Assumptions sheet.
B4: Driver | C4: FY2023A | D4: FY2024A | E4: FY2025A | F4: FY2026E | G4: FY2027E | H4: FY2028E | I4: FY2029E | J4: FY2030E
A5: Forecast year | F5: 1 | G5: 2 | H5: 3 | I5: 4 | J5: 5
A7: REVENUE BUILD
A8: Game & Network Services | C8: =Historical!$D$6 | D8: =Historical!$E$6 | E8: =Historical!$F$6 | F8: =E8*(1+F9) | G8: =F8*(1+G9) | H8: =G8*(1+H9) | I8: =H8*(1+I9) | J8: =I8*(1+J9)
A9: growth | B9: start, fading to long-run | C9: =Historical!$D$6/Historical!$C$6-1 | D9: =Historical!$E$6/Historical!$D$6-1 | E9: =Historical!$F$6/Historical!$E$6-1 | F9: =Assumptions!$D$6+(Assumptions!$D$13-Assumptions!$D$6)*(F$5-1)/4+Assumptions!$D$12 | G9: =Assumptions!$D$6+(Assumptions!$D$13-Assumptions!$D$6)*(G$5-1)/4+Assumptions!$D$12 | H9: =Assumptions!$D$6+(Assumptions!$D$13-Assumptions!$D$6)*(H$5-1)/4+Assumptions!$D$12 | I9: =Assumptions!$D$6+(Assumptions!$D$13-Assumptions!$D$6)*(I$5-1)/4+Assumptions!$D$12 | J9: =Assumptions!$D$6+(Assumptions!$D$13-Assumptions!$D$6)*(J$5-1)/4+Assumptions!$D$12
A10: Music | C10: =Historical!$D$7 | D10: =Historical!$E$7 | E10: =Historical!$F$7 | F10: =E10*(1+F11) | G10: =F10*(1+G11) | H10: =G10*(1+H11) | I10: =H10*(1+I11) | J10: =I10*(1+J11)
A11: growth | B11: start, fading to long-run | C11: =Historical!$D$7/Historical!$C$7-1 | D11: =Historical!$E$7/Historical!$D$7-1 | E11: =Historical!$F$7/Historical!$E$7-1 | F11: =Assumptions!$D$7+(Assumptions!$D$13-Assumptions!$D$7)*(F$5-1)/4+Assumptions!$D$12 | G11: =Assumptions!$D$7+(Assumptions!$D$13-Assumptions!$D$7)*(G$5-1)/4+Assumptions!$D$12 | H11: =Assumptions!$D$7+(Assumptions!$D$13-Assumptions!$D$7)*(H$5-1)/4+Assumptions!$D$12 | I11: =Assumptions!$D$7+(Assumptions!$D$13-Assumptions!$D$7)*(I$5-1)/4+Assumptions!$D$12 | J11: =Assumptions!$D$7+(Assumptions!$D$13-Assumptions!$D$7)*(J$5-1)/4+Assumptions!$D$12
A12: Pictures | C12: =Historical!$D$8 | D12: =Historical!$E$8 | E12: =Historical!$F$8 | F12: =E12*(1+F13) | G12: =F12*(1+G13) | H12: =G12*(1+H13) | I12: =H12*(1+I13) | J12: =I12*(1+J13)
A13: growth | B13: start, fading to long-run | C13: =Historical!$D$8/Historical!$C$8-1 | D13: =Historical!$E$8/Historical!$D$8-1 | E13: =Historical!$F$8/Historical!$E$8-1 | F13: =Assumptions!$D$8+(Assumptions!$D$13-Assumptions!$D$8)*(F$5-1)/4+Assumptions!$D$12 | G13: =Assumptions!$D$8+(Assumptions!$D$13-Assumptions!$D$8)*(G$5-1)/4+Assumptions!$D$12 | H13: =Assumptions!$D$8+(Assumptions!$D$13-Assumptions!$D$8)*(H$5-1)/4+Assumptions!$D$12 | I13: =Assumptions!$D$8+(Assumptions!$D$13-Assumptions!$D$8)*(I$5-1)/4+Assumptions!$D$12 | J13: =Assumptions!$D$8+(Assumptions!$D$13-Assumptions!$D$8)*(J$5-1)/4+Assumptions!$D$12
A14: Entertainment Technology & Services | C14: =Historical!$D$9 | D14: =Historical!$E$9 | E14: =Historical!$F$9 | F14: =E14*(1+F15) | G14: =F14*(1+G15) | H14: =G14*(1+H15) | I14: =H14*(1+I15) | J14: =I14*(1+J15)
A15: growth | B15: start, fading to long-run | C15: =Historical!$D$9/Historical!$C$9-1 | D15: =Historical!$E$9/Historical!$D$9-1 | E15: =Historical!$F$9/Historical!$E$9-1 | F15: =Assumptions!$D$9+(Assumptions!$D$13-Assumptions!$D$9)*(F$5-1)/4+Assumptions!$D$12 | G15: =Assumptions!$D$9+(Assumptions!$D$13-Assumptions!$D$9)*(G$5-1)/4+Assumptions!$D$12 | H15: =Assumptions!$D$9+(Assumptions!$D$13-Assumptions!$D$9)*(H$5-1)/4+Assumptions!$D$12 | I15: =Assumptions!$D$9+(Assumptions!$D$13-Assumptions!$D$9)*(I$5-1)/4+Assumptions!$D$12 | J15: =Assumptions!$D$9+(Assumptions!$D$13-Assumptions!$D$9)*(J$5-1)/4+Assumptions!$D$12
A16: Imaging & Sensing Solutions | C16: =Historical!$D$10 | D16: =Historical!$E$10 | E16: =Historical!$F$10 | F16: =E16*(1+F17) | G16: =F16*(1+G17) | H16: =G16*(1+H17) | I16: =H16*(1+I17) | J16: =I16*(1+J17)
A17: growth | B17: start, fading to long-run | C17: =Historical!$D$10/Historical!$C$10-1 | D17: =Historical!$E$10/Historical!$D$10-1 | E17: =Historical!$F$10/Historical!$E$10-1 | F17: =Assumptions!$D$10+(Assumptions!$D$13-Assumptions!$D$10)*(F$5-1)/4+Assumptions!$D$12 | G17: =Assumptions!$D$10+(Assumptions!$D$13-Assumptions!$D$10)*(G$5-1)/4+Assumptions!$D$12 | H17: =Assumptions!$D$10+(Assumptions!$D$13-Assumptions!$D$10)*(H$5-1)/4+Assumptions!$D$12 | I17: =Assumptions!$D$10+(Assumptions!$D$13-Assumptions!$D$10)*(I$5-1)/4+Assumptions!$D$12 | J17: =Assumptions!$D$10+(Assumptions!$D$13-Assumptions!$D$10)*(J$5-1)/4+Assumptions!$D$12
A18: All Other | C18: =Historical!$D$11 | D18: =Historical!$E$11 | E18: =Historical!$F$11 | F18: =E18*(1+F19) | G18: =F18*(1+G19) | H18: =G18*(1+H19) | I18: =H18*(1+I19) | J18: =I18*(1+J19)
A19: growth | B19: start, fading to long-run | C19: =Historical!$D$11/Historical!$C$11-1 | D19: =Historical!$E$11/Historical!$D$11-1 | E19: =Historical!$F$11/Historical!$E$11-1 | F19: =Assumptions!$D$11+(Assumptions!$D$13-Assumptions!$D$11)*(F$5-1)/4+Assumptions!$D$12 | G19: =Assumptions!$D$11+(Assumptions!$D$13-Assumptions!$D$11)*(G$5-1)/4+Assumptions!$D$12 | H19: =Assumptions!$D$11+(Assumptions!$D$13-Assumptions!$D$11)*(H$5-1)/4+Assumptions!$D$12 | I19: =Assumptions!$D$11+(Assumptions!$D$13-Assumptions!$D$11)*(I$5-1)/4+Assumptions!$D$12 | J19: =Assumptions!$D$11+(Assumptions!$D$13-Assumptions!$D$11)*(J$5-1)/4+Assumptions!$D$12
A20: Segment sales | C20: =C8+C10+C12+C14+C16+C18 | D20: =D8+D10+D12+D14+D16+D18 | E20: =E8+E10+E12+E14+E16+E18 | F20: =F8+F10+F12+F14+F16+F18 | G20: =G8+G10+G12+G14+G16+G18 | H20: =H8+H10+H12+H14+H16+H18 | I20: =I8+I10+I12+I14+I16+I18 | J20: =J8+J10+J12+J14+J16+J18
A21: Corporate and elimination | B21: % of segment sales | C21: =Historical!$D$14-C20 | D21: =Historical!$E$14-D20 | E21: =Historical!$F$14-E20 | F21: =-Assumptions!$D$14*F20 | G21: =-Assumptions!$D$14*G20 | H21: =-Assumptions!$D$14*H20 | I21: =-Assumptions!$D$14*I20 | J21: =-Assumptions!$D$14*J20
A23: INCOME STATEMENT
A24: Sales | C24: =Historical!$D$14 | D24: =Historical!$E$14 | E24: =Historical!$F$14 | F24: =F20+F21 | G24: =G20+G21 | H24: =H20+H21 | I24: =I20+I21 | J24: =J20+J21
A25: growth | D25: =D24/C24-1 | E25: =E24/D24-1 | F25: =F24/E24-1 | G25: =G24/F24-1 | H25: =H24/G24-1 | I25: =I24/H24-1 | J25: =J24/I24-1
A26: Cost of sales | B26: % of sales | C26: =Historical!$D$15 | D26: =Historical!$E$15 | E26: =Historical!$F$15 | F26: =Assumptions!$D$16*F24 | G26: =Assumptions!$D$16*G24 | H26: =Assumptions!$D$16*H24 | I26: =Assumptions!$D$16*I24 | J26: =Assumptions!$D$16*J24
A27: Gross profit | C27: =C24-C26 | D27: =D24-D26 | E27: =E24-E26 | F27: =F24-F26 | G27: =G24-G26 | H27: =H24-H26 | I27: =I24-I26 | J27: =J24-J26
A28: Selling, general and administrative | B28: % of sales | C28: =Historical!$D$16 | D28: =Historical!$E$16 | E28: =Historical!$F$16 | F28: =Assumptions!$D$17*F24 | G28: =Assumptions!$D$17*G24 | H28: =Assumptions!$D$17*H24 | I28: =Assumptions!$D$17*I24 | J28: =Assumptions!$D$17*J24
A29: Other operating (income) expense, net | B29: assumed nil | C29: =Historical!$D$17 | D29: =Historical!$E$17 | E29: =Historical!$F$17 | F29: =0 | G29: =0 | H29: =0 | I29: =0 | J29: =0
A30: Share of profit (loss) of equity-method investments | B30: assumed nil | C30: =Historical!$D$18 | D30: =Historical!$E$18 | E30: =Historical!$F$18 | F30: =0 | G30: =0 | H30: =0 | I30: =0 | J30: =0
A31: Operating income | C31: =C27-C28-C29+C30 | D31: =D27-D28-D29+D30 | E31: =E27-E28-E29+E30 | F31: =F27-F28-F29+F30 | G31: =G27-G28-G29+G30 | H31: =H27-H28-H29+H30 | I31: =I27-I28-I29+I30 | J31: =J27-J28-J29+J30
A32: operating margin | C32: =C31/C24 | D32: =D31/D24 | E32: =E31/E24 | F32: =F31/F24 | G32: =G31/G24 | H32: =H31/H24 | I32: =I31/I24 | J32: =J31/J24
A33: Financial income | B33: % of opening cash | C33: =Historical!$D$20 | D33: =Historical!$E$20 | E33: =Historical!$F$20 | F33: =Assumptions!$D$29*E42 | G33: =Assumptions!$D$29*F42 | H33: =Assumptions!$D$29*G42 | I33: =Assumptions!$D$29*H42 | J33: =Assumptions!$D$29*I42
A34: Financial expenses | B34: % of opening debt | C34: =Historical!$D$21 | D34: =Historical!$E$21 | E34: =Historical!$F$21 | F34: =Assumptions!$D$30*(E53+E54) | G34: =Assumptions!$D$30*(F53+F54) | H34: =Assumptions!$D$30*(G53+G54) | I34: =Assumptions!$D$30*(H53+H54) | J34: =Assumptions!$D$30*(I53+I54)
A35: Income before income taxes | C35: =C31+C33-C34 | D35: =D31+D33-D34 | E35: =E31+E33-E34 | F35: =F31+F33-F34 | G35: =G31+G33-G34 | H35: =H31+H33-H34 | I35: =I31+I33-I34 | J35: =J31+J33-J34
A36: Income taxes | B36: % of pre-tax income | C36: =Historical!$D$23 | D36: =Historical!$E$23 | E36: =Historical!$F$23 | F36: =Assumptions!$D$21*F35 | G36: =Assumptions!$D$21*G35 | H36: =Assumptions!$D$21*H35 | I36: =Assumptions!$D$21*I35 | J36: =Assumptions!$D$21*J35
A37: Net income from continuing operations | C37: =C35-C36 | D37: =D35-D36 | E37: =E35-E36 | F37: =F35-F36 | G37: =G35-G36 | H37: =H35-H36 | I37: =I35-I36 | J37: =J35-J36
A38: Depreciation and amortization (memo) | B38: % of sales | C38: =Historical!$D$27 | D38: =Historical!$E$27 | E38: =Historical!$F$27 | F38: =Assumptions!$D$18*F24 | G38: =Assumptions!$D$18*G24 | H38: =Assumptions!$D$18*H24 | I38: =Assumptions!$D$18*I24 | J38: =Assumptions!$D$18*J24
A39: EBITDA | C39: =C31+C38 | D39: =D31+D38 | E39: =E31+E38 | F39: =F31+F38 | G39: =G31+G38 | H39: =H31+H38 | I39: =I31+I38 | J39: =J31+J38
A41: BALANCE SHEET (March 31 following the fiscal year)
A42: Cash and cash equivalents | B42: from cash flow | D42: =Historical!$E$30 | E42: =Historical!$F$30 | F42: =F78 | G42: =G78 | H42: =H78 | I42: =I78 | J42: =J78
A43: Trade and other receivables | B43: days of sales | D43: =Historical!$E$32 | E43: =Historical!$F$32 | F43: =Assumptions!$D$23/365*F24 | G43: =Assumptions!$D$23/365*G24 | H43: =Assumptions!$D$23/365*H24 | I43: =Assumptions!$D$23/365*I24 | J43: =Assumptions!$D$23/365*J24
A44: Inventories | B44: days of cost of sales | D44: =Historical!$E$33 | E44: =Historical!$F$33 | F44: =Assumptions!$D$24/365*F26 | G44: =Assumptions!$D$24/365*G26 | H44: =Assumptions!$D$24/365*H26 | I44: =Assumptions!$D$24/365*I26 | J44: =Assumptions!$D$24/365*J26
...

Sheet Downside
A1: Sony Group — Downside case: three statements and DCF
A2: ¥ millions unless stated. A = reported, E = forecast. Every forecast cell is a formula driven by the Downside column of the Assumptions sheet.
B4: Driver | C4: FY2023A | D4: FY2024A | E4: FY2025A | F4: FY2026E | G4: FY2027E | H4: FY2028E | I4: FY2029E | J4: FY2030E
A5: Forecast year | F5: 1 | G5: 2 | H5: 3 | I5: 4 | J5: 5
A7: REVENUE BUILD
A8: Game & Network Services | C8: =Historical!$D$6 | D8: =Historical!$E$6 | E8: =Historical!$F$6 | F8: =E8*(1+F9) | G8: =F8*(1+G9) | H8: =G8*(1+H9) | I8: =H8*(1+I9) | J8: =I8*(1+J9)
A9: growth | B9: start, fading to long-run | C9: =Historical!$D$6/Historical!$C$6-1 | D9: =Historical!$E$6/Historical!$D$6-1 | E9: =Historical!$F$6/Historical!$E$6-1 | F9: =Assumptions!$E$6+(Assumptions!$E$13-Assumptions!$E$6)*(F$5-1)/4+Assumptions!$E$12 | G9: =Assumptions!$E$6+(Assumptions!$E$13-Assumptions!$E$6)*(G$5-1)/4+Assumptions!$E$12 | H9: =Assumptions!$E$6+(Assumptions!$E$13-Assumptions!$E$6)*(H$5-1)/4+Assumptions!$E$12 | I9: =Assumptions!$E$6+(Assumptions!$E$13-Assumptions!$E$6)*(I$5-1)/4+Assumptions!$E$12 | J9: =Assumptions!$E$6+(Assumptions!$E$13-Assumptions!$E$6)*(J$5-1)/4+Assumptions!$E$12
A10: Music | C10: =Historical!$D$7 | D10: =Historical!$E$7 | E10: =Historical!$F$7 | F10: =E10*(1+F11) | G10: =F10*(1+G11) | H10: =G10*(1+H11) | I10: =H10*(1+I11) | J10: =I10*(1+J11)
A11: growth | B11: start, fading to long-run | C11: =Historical!$D$7/Historical!$C$7-1 | D11: =Historical!$E$7/Historical!$D$7-1 | E11: =Historical!$F$7/Historical!$E$7-1 | F11: =Assumptions!$E$7+(Assumptions!$E$13-Assumptions!$E$7)*(F$5-1)/4+Assumptions!$E$12 | G11: =Assumptions!$E$7+(Assumptions!$E$13-Assumptions!$E$7)*(G$5-1)/4+Assumptions!$E$12 | H11: =Assumptions!$E$7+(Assumptions!$E$13-Assumptions!$E$7)*(H$5-1)/4+Assumptions!$E$12 | I11: =Assumptions!$E$7+(Assumptions!$E$13-Assumptions!$E$7)*(I$5-1)/4+Assumptions!$E$12 | J11: =Assumptions!$E$7+(Assumptions!$E$13-Assumptions!$E$7)*(J$5-1)/4+Assumptions!$E$12
A12: Pictures | C12: =Historical!$D$8 | D12: =Historical!$E$8 | E12: =Historical!$F$8 | F12: =E12*(1+F13) | G12: =F12*(1+G13) | H12: =G12*(1+H13) | I12: =H12*(1+I13) | J12: =I12*(1+J13)
A13: growth | B13: start, fading to long-run | C13: =Historical!$D$8/Historical!$C$8-1 | D13: =Historical!$E$8/Historical!$D$8-1 | E13: =Historical!$F$8/Historical!$E$8-1 | F13: =Assumptions!$E$8+(Assumptions!$E$13-Assumptions!$E$8)*(F$5-1)/4+Assumptions!$E$12 | G13: =Assumptions!$E$8+(Assumptions!$E$13-Assumptions!$E$8)*(G$5-1)/4+Assumptions!$E$12 | H13: =Assumptions!$E$8+(Assumptions!$E$13-Assumptions!$E$8)*(H$5-1)/4+Assumptions!$E$12 | I13: =Assumptions!$E$8+(Assumptions!$E$13-Assumptions!$E$8)*(I$5-1)/4+Assumptions!$E$12 | J13: =Assumptions!$E$8+(Assumptions!$E$13-Assumptions!$E$8)*(J$5-1)/4+Assumptions!$E$12
A14: Entertainment Technology & Services | C14: =Historical!$D$9 | D14: =Historical!$E$9 | E14: =Historical!$F$9 | F14: =E14*(1+F15) | G14: =F14*(1+G15) | H14: =G14*(1+H15) | I14: =H14*(1+I15) | J14: =I14*(1+J15)
A15: growth | B15: start, fading to long-run | C15: =Historical!$D$9/Historical!$C$9-1 | D15: =Historical!$E$9/Historical!$D$9-1 | E15: =Historical!$F$9/Historical!$E$9-1 | F15: =Assumptions!$E$9+(Assumptions!$E$13-Assumptions!$E$9)*(F$5-1)/4+Assumptions!$E$12 | G15: =Assumptions!$E$9+(Assumptions!$E$13-Assumptions!$E$9)*(G$5-1)/4+Assumptions!$E$12 | H15: =Assumptions!$E$9+(Assumptions!$E$13-Assumptions!$E$9)*(H$5-1)/4+Assumptions!$E$12 | I15: =Assumptions!$E$9+(Assumptions!$E$13-Assumptions!$E$9)*(I$5-1)/4+Assumptions!$E$12 | J15: =Assumptions!$E$9+(Assumptions!$E$13-Assumptions!$E$9)*(J$5-1)/4+Assumptions!$E$12
A16: Imaging & Sensing Solutions | C16: =Historical!$D$10 | D16: =Historical!$E$10 | E16: =Historical!$F$10 | F16: =E16*(1+F17) | G16: =F16*(1+G17) | H16: =G16*(1+H17) | I16: =H16*(1+I17) | J16: =I16*(1+J17)
A17: growth | B17: start, fading to long-run | C17: =Historical!$D$10/Historical!$C$10-1 | D17: =Historical!$E$10/Historical!$D$10-1 | E17: =Historical!$F$10/Historical!$E$10-1 | F17: =Assumptions!$E$10+(Assumptions!$E$13-Assumptions!$E$10)*(F$5-1)/4+Assumptions!$E$12 | G17: =Assumptions!$E$10+(Assumptions!$E$13-Assumptions!$E$10)*(G$5-1)/4+Assumptions!$E$12 | H17: =Assumptions!$E$10+(Assumptions!$E$13-Assumptions!$E$10)*(H$5-1)/4+Assumptions!$E$12 | I17: =Assumptions!$E$10+(Assumptions!$E$13-Assumptions!$E$10)*(I$5-1)/4+Assumptions!$E$12 | J17: =Assumptions!$E$10+(Assumptions!$E$13-Assumptions!$E$10)*(J$5-1)/4+Assumptions!$E$12
A18: All Other | C18: =Historical!$D$11 | D18: =Historical!$E$11 | E18: =Historical!$F$11 | F18: =E18*(1+F19) | G18: =F18*(1+G19) | H18: =G18*(1+H19) | I18: =H18*(1+I19) | J18: =I18*(1+J19)
A19: growth | B19: start, fading to long-run | C19: =Historical!$D$11/Historical!$C$11-1 | D19: =Historical!$E$11/Historical!$D$11-1 | E19: =Historical!$F$11/Historical!$E$11-1 | F19: =Assumptions!$E$11+(Assumptions!$E$13-Assumptions!$E$11)*(F$5-1)/4+Assumptions!$E$12 | G19: =Assumptions!$E$11+(Assumptions!$E$13-Assumptions!$E$11)*(G$5-1)/4+Assumptions!$E$12 | H19: =Assumptions!$E$11+(Assumptions!$E$13-Assumptions!$E$11)*(H$5-1)/4+Assumptions!$E$12 | I19: =Assumptions!$E$11+(Assumptions!$E$13-Assumptions!$E$11)*(I$5-1)/4+Assumptions!$E$12 | J19: =Assumptions!$E$11+(Assumptions!$E$13-Assumptions!$E$11)*(J$5-1)/4+Assumptions!$E$12
A20: Segment sales | C20: =C8+C10+C12+C14+C16+C18 | D20: =D8+D10+D12+D14+D16+D18 | E20: =E8+E10+E12+E14+E16+E18 | F20: =F8+F10+F12+F14+F16+F18 | G20: =G8+G10+G12+G14+G16+G18 | H20: =H8+H10+H12+H14+H16+H18 | I20: =I8+I10+I12+I14+I16+I18 | J20: =J8+J10+J12+J14+J16+J18
A21: Corporate and elimination | B21: % of segment sales | C21: =Historical!$D$14-C20 | D21: =Historical!$E$14-D20 | E21: =Historical!$F$14-E20 | F21: =-Assumptions!$E$14*F20 | G21: =-Assumptions!$E$14*G20 | H21: =-Assumptions!$E$14*H20 | I21: =-Assumptions!$E$14*I20 | J21: =-Assumptions!$E$14*J20
A23: INCOME STATEMENT
A24: Sales | C24: =Historical!$D$14 | D24: =Historical!$E$14 | E24: =Historical!$F$14 | F24: =F20+F21 | G24: =G20+G21 | H24: =H20+H21 | I24: =I20+I21 | J24: =J20+J21
A25: growth | D25: =D24/C24-1 | E25: =E24/D24-1 | F25: =F24/E24-1 | G25: =G24/F24-1 | H25: =H24/G24-1 | I25: =I24/H24-1 | J25: =J24/I24-1
A26: Cost of sales | B26: % of sales | C26: =Historical!$D$15 | D26: =Historical!$E$15 | E26: =Historical!$F$15 | F26: =Assumptions!$E$16*F24 | G26: =Assumptions!$E$16*G24 | H26: =Assumptions!$E$16*H24 | I26: =Assumptions!$E$16*I24 | J26: =Assumptions!$E$16*J24
A27: Gross profit | C27: =C24-C26 | D27: =D24-D26 | E27: =E24-E26 | F27: =F24-F26 | G27: =G24-G26 | H27: =H24-H26 | I27: =I24-I26 | J27: =J24-J26
A28: Selling, general and administrative | B28: % of sales | C28: =Historical!$D$16 | D28: =Historical!$E$16 | E28: =Historical!$F$16 | F28: =Assumptions!$E$17*F24 | G28: =Assumptions!$E$17*G24 | H28: =Assumptions!$E$17*H24 | I28: =Assumptions!$E$17*I24 | J28: =Assumptions!$E$17*J24
A29: Other operating (income) expense, net | B29: assumed nil | C29: =Historical!$D$17 | D29: =Historical!$E$17 | E29: =Historical!$F$17 | F29: =0 | G29: =0 | H29: =0 | I29: =0 | J29: =0
A30: Share of profit (loss) of equity-method investments | B30: assumed nil | C30: =Historical!$D$18 | D30: =Historical!$E$18 | E30: =Historical!$F$18 | F30: =0 | G30: =0 | H30: =0 | I30: =0 | J30: =0
A31: Operating income | C31: =C27-C28-C29+C30 | D31: =D27-D28-D29+D30 | E31: =E27-E28-E29+E30 | F31: =F27-F28-F29+F30 | G31: =G27-G28-G29+G30 | H31: =H27-H28-H29+H30 | I31: =I27-I28-I29+I30 | J31: =J27-J28-J29+J30
A32: operating margin | C32: =C31/C24 | D32: =D31/D24 | E32: =E31/E24 | F32: =F31/F24 | G32: =G31/G24 | H32: =H31/H24 | I32: =I31/I24 | J32: =J31/J24
A33: Financial income | B33: % of opening cash | C33: =Historical!$D$20 | D33: =Historical!$E$20 | E33: =Historical!$F$20 | F33: =Assumptions!$E$29*E42 | G33: =Assumptions!$E$29*F42 | H33: =Assumptions!$E$29*G42 | I33: =Assumptions!$E$29*H42 | J33: =Assumptions!$E$29*I42
A34: Financial expenses | B34: % of opening debt | C34: =Historical!$D$21 | D34: =Historical!$E$21 | E34: =Historical!$F$21 | F34: =Assumptions!$E$30*(E53+E54) | G34: =Assumptions!$E$30*(F53+F54) | H34: =Assumptions!$E$30*(G53+G54) | I34: =Assumptions!$E$30*(H53+H54) | J34: =Assumptions!$E$30*(I53+I54)
A35: Income before income taxes | C35: =C31+C33-C34 | D35: =D31+D33-D34 | E35: =E31+E33-E34 | F35: =F31+F33-F34 | G35: =G31+G33-G34 | H35: =H31+H33-H34 | I35: =I31+I33-I34 | J35: =J31+J33-J34
A36: Income taxes | B36: % of pre-tax income | C36: =Historical!$D$23 | D36: =Historical!$E$23 | E36: =Historical!$F$23 | F36: =Assumptions!$E$21*F35 | G36: =Assumptions!$E$21*G35 | H36: =Assumptions!$E$21*H35 | I36: =Assumptions!$E$21*I35 | J36: =Assumptions!$E$21*J35
A37: Net income from continuing operations | C37: =C35-C36 | D37: =D35-D36 | E37: =E35-E36 | F37: =F35-F36 | G37: =G35-G36 | H37: =H35-H36 | I37: =I35-I36 | J37: =J35-J36
A38: Depreciation and amortization (memo) | B38: % of sales | C38: =Historical!$D$27 | D38: =Historical!$E$27 | E38: =Historical!$F$27 | F38: =Assumptions!$E$18*F24 | G38: =Assumptions!$E$18*G24 | H38: =Assumptions!$E$18*H24 | I38: =Assumptions!$E$18*I24 | J38: =Assumptions!$E$18*J24
A39: EBITDA | C39: =C31+C38 | D39: =D31+D38 | E39: =E31+E38 | F39: =F31+F38 | G39: =G31+G38 | H39: =H31+H38 | I39: =I31+I38 | J39: =J31+J38
A41: BALANCE SHEET (March 31 following the fiscal year)
A42: Cash and cash equivalents | B42: from cash flow | D42: =Historical!$E$30 | E42: =Historical!$F$30 | F42: =F78 | G42: =G78 | H42: =H78 | I42: =I78 | J42: =J78
A43: Trade and other receivables | B43: days of sales | D43: =Historical!$E$32 | E43: =Historical!$F$32 | F43: =Assumptions!$E$23/365*F24 | G43: =Assumptions!$E$23/365*G24 | H43: =Assumptions!$E$23/365*H24 | I43: =Assumptions!$E$23/365*I24 | J43: =Assumptions!$E$23/365*J24
A44: Inventories | B44: days of cost of sales | D44: =Historical!$E$33 | E44: =Historical!$F$33 | F44: =Assumptions!$E$24/365*F26 | G44: =Assumptions!$E$24/365*G26 | H44: =Assumptions!$E$24/365*H26 | I44: =Assumptions!$E$24/365*I26 | J44: =Assumptions!$E$24/365*J26
...

Sheet Scenarios
A1: Scenario comparison and sensitivity
A2: Every figure links to the Base, Upside and Downside sheets; change an assumption and this page updates.
A4: ¥ millions unless stated | B4: Base | C4: Upside | D4: Downside
A5: Growth adjustment (points per year) | B5: =Assumptions!$C$12 | C5: =Assumptions!$D$12 | D5: =Assumptions!$E$12
A6: Cost of sales (% of sales) | B6: =Assumptions!$C$16 | C6: =Assumptions!$D$16 | D6: =Assumptions!$E$16
A7: Terminal growth rate | B7: =Assumptions!$C$35 | C7: =Assumptions!$D$35 | D7: =Assumptions!$E$35
A8: FY2030 sales | B8: =Base!J24 | C8: =Upside!J24 | D8: =Downside!J24
A9: Sales CAGR, FY2025–FY2030 | B9: =(Base!J24/Base!E24)^(1/5)-1 | C9: =(Upside!J24/Upside!E24)^(1/5)-1 | D9: =(Downside!J24/Downside!E24)^(1/5)-1
A10: FY2030 operating income | B10: =Base!J31 | C10: =Upside!J31 | D10: =Downside!J31
A11: FY2030 operating margin | B11: =Base!J32 | C11: =Upside!J32 | D11: =Downside!J32
A12: Free cash flow, FY2026–FY2030 total | B12: =SUM(Base!F88:J88) | C12: =SUM(Upside!F88:J88) | D12: =SUM(Downside!F88:J88)
A13: Enterprise value | B13: =Base!C98 | C13: =Upside!C98 | D13: =Downside!C98
A14: Equity value | B14: =Base!C106 | C14: =Upside!C106 | D14: =Downside!C106
A15: Value per share (¥) | B15: =Base!C107 | C15: =Upside!C107 | D15: =Downside!C107
A16: Value per ADR (US$) | B16: =Base!C108 | C16: =Upside!C108 | D16: =Downside!C108
A17: Market price per share (¥) | B17: =Base!C109 | C17: =Upside!C109 | D17: =Downside!C109
A18: Value versus market price | B18: =Base!C110 | C18: =Upside!C110 | D18: =Downside!C110
A19: Terminal value as share of enterprise value | B19: =Base!C111 | C19: =Upside!C111 | D19: =Downside!C111
A20: Balance check, all forecast years (must be zero) | B20: =SUM(Base!F60:J60) | C20: =SUM(Upside!F60:J60) | D20: =SUM(Downside!F60:J60)
A23: Sensitivity: Base-case value per share (¥) to WACC and terminal growth
A24: Rows: WACC. Columns: terminal growth. The centre cell equals the Base-case value per share.
A25: WACC \ terminal growth | B25: =Assumptions!$C$35-0.01 | C25: =Assumptions!$C$35-0.005 | D25: =Assumptions!$C$35+0 | E25: =Assumptions!$C$35+0.005 | F25: =Assumptions!$C$35+0.01
A26: =Assumptions!$C$50-0.02 | B26: =(SUMPRODUCT(Base!$F$88:$J$88/(1+$A26)^Base!$F$5:$J$5)+Base!$J$88*(1+B$25)/($A26-B$25)/(1+$A26)^5+Base!$C$105)*1000000/Assumptions!$C$42 | C26: =(SUMPRODUCT(Base!$F$88:$J$88/(1+$A26)^Base!$F$5:$J$5)+Base!$J$88*(1+C$25)/($A26-C$25)/(1+$A26)^5+Base!$C$105)*1000000/Assumptions!$C$42 | D26: =(SUMPRODUCT(Base!$F$88:$J$88/(1+$A26)^Base!$F$5:$J$5)+Base!$J$88*(1+D$25)/($A26-D$25)/(1+$A26)^5+Base!$C$105)*1000000/Assumptions!$C$42 | E26: =(SUMPRODUCT(Base!$F$88:$J$88/(1+$A26)^Base!$F$5:$J$5)+Base!$J$88*(1+E$25)/($A26-E$25)/(1+$A26)^5+Base!$C$105)*1000000/Assumptions!$C$42 | F26: =(SUMPRODUCT(Base!$F$88:$J$88/(1+$A26)^Base!$F$5:$J$5)+Base!$J$88*(1+F$25)/($A26-F$25)/(1+$A26)^5+Base!$C$105)*1000000/Assumptions!$C$42
A27: =Assumptions!$C$50-0.01 | B27: =(SUMPRODUCT(Base!$F$88:$J$88/(1+$A27)^Base!$F$5:$J$5)+Base!$J$88*(1+B$25)/($A27-B$25)/(1+$A27)^5+Base!$C$105)*1000000/Assumptions!$C$42 | C27: =(SUMPRODUCT(Base!$F$88:$J$88/(1+$A27)^Base!$F$5:$J$5)+Base!$J$88*(1+C$25)/($A27-C$25)/(1+$A27)^5+Base!$C$105)*1000000/Assumptions!$C$42 | D27: =(SUMPRODUCT(Base!$F$88:$J$88/(1+$A27)^Base!$F$5:$J$5)+Base!$J$88*(1+D$25)/($A27-D$25)/(1+$A27)^5+Base!$C$105)*1000000/Assumptions!$C$42 | E27: =(SUMPRODUCT(Base!$F$88:$J$88/(1+$A27)^Base!$F$5:$J$5)+Base!$J$88*(1+E$25)/($A27-E$25)/(1+$A27)^5+Base!$C$105)*1000000/Assumptions!$C$42 | F27: =(SUMPRODUCT(Base!$F$88:$J$88/(1+$A27)^Base!$F$5:$J$5)+Base!$J$88*(1+F$25)/($A27-F$25)/(1+$A27)^5+Base!$C$105)*1000000/Assumptions!$C$42
A28: =Assumptions!$C$50+0 | B28: =(SUMPRODUCT(Base!$F$88:$J$88/(1+$A28)^Base!$F$5:$J$5)+Base!$J$88*(1+B$25)/($A28-B$25)/(1+$A28)^5+Base!$C$105)*1000000/Assumptions!$C$42 | C28: =(SUMPRODUCT(Base!$F$88:$J$88/(1+$A28)^Base!$F$5:$J$5)+Base!$J$88*(1+C$25)/($A28-C$25)/(1+$A28)^5+Base!$C$105)*1000000/Assumptions!$C$42 | D28: =(SUMPRODUCT(Base!$F$88:$J$88/(1+$A28)^Base!$F$5:$J$5)+Base!$J$88*(1+D$25)/($A28-D$25)/(1+$A28)^5+Base!$C$105)*1000000/Assumptions!$C$42 | E28: =(SUMPRODUCT(Base!$F$88:$J$88/(1+$A28)^Base!$F$5:$J$5)+Base!$J$88*(1+E$25)/($A28-E$25)/(1+$A28)^5+Base!$C$105)*1000000/Assumptions!$C$42 | F28: =(SUMPRODUCT(Base!$F$88:$J$88/(1+$A28)^Base!$F$5:$J$5)+Base!$J$88*(1+F$25)/($A28-F$25)/(1+$A28)^5+Base!$C$105)*1000000/Assumptions!$C$42
A29: =Assumptions!$C$50+0.01 | B29: =(SUMPRODUCT(Base!$F$88:$J$88/(1+$A29)^Base!$F$5:$J$5)+Base!$J$88*(1+B$25)/($A29-B$25)/(1+$A29)^5+Base!$C$105)*1000000/Assumptions!$C$42 | C29: =(SUMPRODUCT(Base!$F$88:$J$88/(1+$A29)^Base!$F$5:$J$5)+Base!$J$88*(1+C$25)/($A29-C$25)/(1+$A29)^5+Base!$C$105)*1000000/Assumptions!$C$42 | D29: =(SUMPRODUCT(Base!$F$88:$J$88/(1+$A29)^Base!$F$5:$J$5)+Base!$J$88*(1+D$25)/($A29-D$25)/(1+$A29)^5+Base!$C$105)*1000000/Assumptions!$C$42 | E29: =(SUMPRODUCT(Base!$F$88:$J$88/(1+$A29)^Base!$F$5:$J$5)+Base!$J$88*(1+E$25)/($A29-E$25)/(1+$A29)^5+Base!$C$105)*1000000/Assumptions!$C$42 | F29: =(SUMPRODUCT(Base!$F$88:$J$88/(1+$A29)^Base!$F$5:$J$5)+Base!$J$88*(1+F$25)/($A29-F$25)/(1+$A29)^5+Base!$C$105)*1000000/Assumptions!$C$42
A30: =Assumptions!$C$50+0.02 | B30: =(SUMPRODUCT(Base!$F$88:$J$88/(1+$A30)^Base!$F$5:$J$5)+Base!$J$88*(1+B$25)/($A30-B$25)/(1+$A30)^5+Base!$C$105)*1000000/Assumptions!$C$42 | C30: =(SUMPRODUCT(Base!$F$88:$J$88/(1+$A30)^Base!$F$5:$J$5)+Base!$J$88*(1+C$25)/($A30-C$25)/(1+$A30)^5+Base!$C$105)*1000000/Assumptions!$C$42 | D30: =(SUMPRODUCT(Base!$F$88:$J$88/(1+$A30)^Base!$F$5:$J$5)+Base!$J$88*(1+D$25)/($A30-D$25)/(1+$A30)^5+Base!$C$105)*1000000/Assumptions!$C$42 | E30: =(SUMPRODUCT(Base!$F$88:$J$88/(1+$A30)^Base!$F$5:$J$5)+Base!$J$88*(1+E$25)/($A30-E$25)/(1+$A30)^5+Base!$C$105)*1000000/Assumptions!$C$42 | F30: =(SUMPRODUCT(Base!$F$88:$J$88/(1+$A30)^Base!$F$5:$J$5)+Base!$J$88*(1+F$25)/($A30-F$25)/(1+$A30)^5+Base!$C$105)*1000000/Assumptions!$C$42
A33: Chart data (feeds the Dashboard)
A34: ¥ trillions | B34: FY2023A | C34: FY2024A | D34: FY2025A | E34: FY2026E | F34: FY2027E | G34: FY2028E | H34: FY2029E | I34: FY2030E
A35: Sales — Base | B35: =Base!C24/1000000 | C35: =Base!D24/1000000 | D35: =Base!E24/1000000 | E35: =Base!F24/1000000 | F35: =Base!G24/1000000 | G35: =Base!H24/1000000 | H35: =Base!I24/1000000 | I35: =Base!J24/1000000
A36: Sales — Upside | B36: =Upside!C24/1000000 | C36: =Upside!D24/1000000 | D36: =Upside!E24/1000000 | E36: =Upside!F24/1000000 | F36: =Upside!G24/1000000 | G36: =Upside!H24/1000000 | H36: =Upside!I24/1000000 | I36: =Upside!J24/1000000
A37: Sales — Downside | B37: =Downside!C24/1000000 | C37: =Downside!D24/1000000 | D37: =Downside!E24/1000000 | E37: =Downside!F24/1000000 | F37: =Downside!G24/1000000 | G37: =Downside!H24/1000000 | H37: =Downside!I24/1000000 | I37: =Downside!J24/1000000
A38: Operating income — Base | B38: =Base!C31/1000000 | C38: =Base!D31/1000000 | D38: =Base!E31/1000000 | E38: =Base!F31/1000000 | F38: =Base!G31/1000000 | G38: =Base!H31/1000000 | H38: =Base!I31/1000000 | I38: =Base!J31/1000000
A39: Free cash flow — Base | E39: =Base!F88/1000000 | F39: =Base!G88/1000000 | G39: =Base!H88/1000000 | H39: =Base!I88/1000000 | I39: =Base!J88/1000000
A41: Value per share (¥) | B41: Base | C41: Upside | D41: Downside | E41: Market price
A42: Value per share (¥) | B42: =Base!C107 | C42: =Upside!C107 | D42: =Downside!C107 | E42: =Assumptions!$C$43
